<?xml version="1.0" ?>
<!-- =================================================================================== -->
<!-- |    This document was autogenerated by xacro from panda_arm_hand.urdf.xacro      | -->
<!-- |    EDITING THIS FILE BY HAND IS NOT RECOMMENDED                                 | -->
<!-- =================================================================================== -->
<robot name="snake_robot" >
  
  <link name="base_footprint">
    <visual>
      <origin xyz="0 0 0" rpy="0 0 0" />
      <geometry>
        <box size="0.001 0.001 0.001" />
      </geometry>
    </visual>
  </link>

  <joint name="sr_joint0" type="fixed">
    <origin xyz="0 0 0" rpy="0 0 0" />
    <parent link="base_footprint"/>
    <child link="sr_link0" />
  </joint>

  <link name="sr_link0">
    <inertial>
      <mass value="10" />
      <origin xyz="0 0 0" />
      <inertia ixx="5.0" ixy="0.0" ixz="0.0"
               iyy="5.0" iyz="0.0"
               izz="5.0" />
    </inertial>
    <visual>
      <origin xyz="0 0 0" rpy="0 0 0" />
      <geometry>
        <sphere radius="0.05"/> <!-- does not need to match collision -->
      </geometry>
    </visual>
    <collision>
      <origin xyz="0 0 0" />
      <geometry>
        <sphere radius="0.05"/>
      </geometry>
    </collision>
  </link>


  <joint name="sr_joint1" type="revolute">
<!--    <safety_controller k_position="100.0" k_velocity="40.0" soft_lower_limit="-2.8973" soft_upper_limit="2.8973"/>-->
    <origin rpy="0 0 0" xyz="0.051 0 0"/>
    <parent link="sr_link0"/>
    <child link="sr_link1"/>
    <axis xyz="0 0 1"/>
    <limit effort="87" lower="-0.785" upper="0.785" velocity="2.1750"/>
  </joint>

  <link name="sr_link1">
    <inertial>
      <origin rpy="0 0 0" xyz="0 0 0"/>
      <mass value="3"/>
      <inertia ixx="1" ixy="0" ixz="0" iyy="1" iyz="0" izz="1"/>
    </inertial>
    <visual>
      <origin rpy="0 1.57 0" xyz="0.16 0 0"/>
      <geometry>
        <cylinder length="0.3" radius="0.05"/>
      </geometry>
        <color rgba="1. 1. 1. 1."/>
    </visual>
    <collision>
      <origin rpy="0 1.57 0" xyz="0.16 0 0"/>
      <geometry>
        <cylinder length="0.3" radius="0.05"/>
      </geometry>
    </collision>
  </link>

    <joint name="sr_joint2" type="revolute">
      <safety_controller k_position="100.0" k_velocity="40.0" soft_lower_limit="-2.8973" soft_upper_limit="2.8973"/>
      <origin rpy="0 0 0" xyz="0.32 0 0"/>
      <parent link="sr_link1"/>
      <child link="sr_link2"/>
      <axis xyz="0 1 0"/>
      <limit effort="87" lower="-0.785" upper="0.785" velocity="2.1750"/>
    </joint>

    <link name="sr_link2">
      <inertial>
        <origin rpy="0 0 0" xyz="0 0 0"/>
        <mass value="3"/>
        <inertia ixx="1" ixy="0" ixz="0" iyy="1" iyz="0" izz="1"/>
      </inertial>
      <visual>
        <origin rpy="0 1.57 0" xyz="0.17 0 0"/>
        <geometry>
          <cylinder length="0.3" radius="0.05"/>
        </geometry>
        <color rgba="1. 1. 1. 1."/>
      </visual>
      <collision>
        <origin rpy="0 1.57 0" xyz="0.17 0 0"/>
        <geometry>
          <cylinder length="0.3" radius="0.05"/>
        </geometry>
      </collision>
    </link>

    <joint name="sr_joint3" type="revolute">
      <safety_controller k_position="100.0" k_velocity="40.0" soft_lower_limit="-2.8973" soft_upper_limit="2.8973"/>
      <origin rpy="0 0 0" xyz="0.32 0 0"/>
      <parent link="sr_link2"/>
      <child link="sr_link3"/>
      <axis xyz="0 0 1"/>
      <limit effort="87" lower="-0.785" upper="0.785" velocity="2.1750"/>
    </joint>

    <link name="sr_link3">
      <inertial>
        <origin rpy="0 0 0" xyz="0 0 0"/>
        <mass value="3"/>
        <inertia ixx="1" ixy="0" ixz="0" iyy="1" iyz="0" izz="1"/>
      </inertial>
      <visual>
        <origin rpy="0 1.57 0" xyz="0.17 0 0"/>
        <geometry>
          <cylinder length="0.3" radius="0.05"/>
        </geometry>
        <color rgba="1. 1. 1. 1."/>
      </visual>
      <collision>
        <origin rpy="0 1.57 0" xyz="0.17 0 0"/>
        <geometry>
          <cylinder length="0.3" radius="0.05"/>
        </geometry>
      </collision>
    </link>

  <gazebo>
    <plugin filename="gz-sim-joint-state-publisher-system"
      name="gz::sim::systems::JointStatePublisher">
      <topic>joint_states</topic>
    </plugin>

    <plugin filename="gz-sim-odometry-publisher-system"
      name="gz::sim::systems::OdometryPublisher">
      <odom_frame>odom</odom_frame>
      <robot_base_frame>base_footprint</robot_base_frame>
      <!-- <dimensions>3</dimensions> -->
    </plugin>
  </gazebo>


</robot>